Workbook

Sheet HuongDan
A1: BIỂU TÍNH LCR THEO THÔNG TƯ 50/2026/TT-NHNN
A3: Mục đích
A4: Công cụ tính nội bộ tỷ lệ khả năng chi trả (LCR) theo Mục 5 Chương II và Phụ lục I TT50/2026/TT-NHNN. Các sheet HQLA, DongTienRa, DongTienVao giữ đúng số mục của Bảng 3, Bảng 6, Bảng 8 trong PL1. KHÔNG phải mẫu báo cáo thống kê chính thức gửi NHNN.
A6: Hiệu lực và phạm vi
A7: • TT50 hiệu lực 01/10/2026; LCR áp dụng từ 01/10/2028 theo lộ trình (Đ13.1, Đ16.1.c), hoặc sớm hơn nếu đăng ký (Đ13.2).
A8: • Trước khi áp dụng LCR/NSFR, ngân hàng tuân thủ các tỷ lệ thanh khoản theo TT22/2019 (Đ13.4). File này KHÔNG tính các tỷ lệ đó.
A9: • Mỗi loại LCR (quy VNĐ, VNĐ, ngoại tệ trọng yếu) và mỗi phạm vi (riêng lẻ, hợp nhất) dùng một bản file riêng.
A11: Thứ tự sheet
A12: KetQua — thông tin báo cáo, lộ trình, kết quả LCR, cảnh báo Đ18.1
A13: HQLA — Bảng 3: HQLA đủ điều kiện, KĐC15%, KĐC40%, hạn mức
A14: DongTienRa — Bảng 6: dòng tiền ra theo 4 time bucket
A15: DongTienVao — Bảng 8: dòng tiền vào theo 4 time bucket
... A36: Dựng ngày 20/10/2026. Node wiki liên quan đang ở maturity draft.

Sheet KetQua
A1: TỶ LỆ KHẢ NĂNG CHI TRẢ (LCR) — TT50/2026/TT-NHNN
A2: Đơn vị: tỷ đồng. Ô nền vàng chữ xanh = nhập liệu. Số liệu trong file là MINH HOẠ.
B4: I. THÔNG TIN BÁO CÁO
B5: Tên ngân hàng | C5: Ngân hàng minh hoạ
B6: Ngày chốt số liệu | C6: 47208
B7: Loại LCR | C7: LCR quy VNĐ | D7: Đ16.1.a: LCR quy VNĐ / LCR VNĐ / LCR ngoại tệ trọng yếu. Mỗi loại dùng một bản file.
B8: Phạm vi | C8: Riêng lẻ | D8: Lộ trình Đ16.1.c chỉ áp cho LCR quy VNĐ riêng lẻ; loại khác dùng ngưỡng nội bộ (ô C12).
B9: Đối tượng áp dụng lộ trình | C9: Đ13.1 | D9: Đ13.1: từ 01/10/2028. Đ13.2.a: đăng ký áp dụng sớm → nhập ô C10.
B10: Ngày đầu tháng sau tháng đăng ký (nếu Đ13.2.a)
B11: Ngày bắt đầu lộ trình | C11: =IF(C9="Đ13.1",ThamSo!$E$82,C10)
B12: Ngưỡng ghi đè (tuỳ chọn) | D12: Để trống để dùng lộ trình. Nhập khi tính LCR VNĐ/ngoại tệ/hợp nhất theo ngưỡng nội bộ, hoặc khi áp ngưỡng 100% theo Đ13.2.b/Đ13.3.
B14: II. LỘ TRÌNH NGƯỠNG TỐI THIỂU (Đ16.1.c, Bảng 1)
B15: Năm áp dụng | C15: Từ ngày | D15: Ngưỡng LCR quy VNĐ riêng lẻ
B16: Năm thứ 1 | C16: =DATE(YEAR($C$11)+0,MONTH($C$11),DAY($C$11)) | D16: =ThamSo!$E$75
B17: Năm thứ 2 | C17: =DATE(YEAR($C$11)+1,MONTH($C$11),DAY($C$11)) | D17: =ThamSo!$E$76
B18: Năm thứ 3 | C18: =DATE(YEAR($C$11)+2,MONTH($C$11),DAY($C$11)) | D18: =ThamSo!$E$77
B19: Năm thứ 4 | C19: =DATE(YEAR($C$11)+3,MONTH($C$11),DAY($C$11)) | D19: =ThamSo!$E$78
B20: Năm thứ 5 | C20: =DATE(YEAR($C$11)+4,MONTH($C$11),DAY($C$11)) | D20: =ThamSo!$E$79
B21: Năm thứ 6 trở đi | C21: =DATE(YEAR($C$11)+5,MONTH($C$11),DAY($C$11)) | D21: =ThamSo!$E$80
B23: III. KẾT QUẢ
B24: Giá trị HQLA đủ điều kiện | C24: =HQLA!G34 | D24: Đ16.1.b; PL1 Phần A
B25: Tổng dòng tiền ra | C25: =DongTienRa!I57 | D25: Đ21.2; PL1 Phần B
B26: Tổng dòng tiền vào (trước trần) | C26: =DongTienVao!I30 | D26: Đ21.2; PL1 Phần C
B27: Trần dòng tiền vào = 75% × Tổng dòng tiền ra | C27: =ThamSo!$E$73*C25 | D27: Đ21.2
B28: Dòng tiền vào được tính = Min(dòng vào, trần) | C28: =MIN(C26,C27)
B29: Tổng dòng tiền ra ròng 30 ngày | C29: =C25-C28 | D29: Tổng dòng tiền ra – Min(Tổng dòng tiền vào, 75% Tổng dòng tiền ra)
B30: Tỷ lệ LCR | C30: =IF(C29>0,C24/C29,"n/a") | D30: LCR = HQLA đủ điều kiện / Dòng tiền ra ròng 30 ngày × 100%
B31: Trạng thái lộ trình | C31: =IF(C6<C11,"Chưa đến lộ trình",INDEX(B16:B21,MATCH(C6,C16:C21,1)))
B32: Ngưỡng theo lộ trình | C32: =IF(C6<C11,0,INDEX(D16:D21,MATCH(C6,C16:C21,1)))
B33: Ngưỡng áp dụng | C33: =IF(C12="",C32,C12)
B34: Kết luận | C34: =IF(NOT(ISNUMBER(C30)),"-",IF(C33=0,"Chỉ theo dõi (chưa có ngưỡng)",IF(C30>=C33,"Đạt","Không đạt")))
B35: HQLA đủ điều kiện phải đáp ứng = Ngưỡng × Dòng tiền ra ròng | C35: =C33*C29
B36: HQLA đủ điều kiện / HQLA phải đáp ứng | C36: =IF(C35>0,C24/C35,"n/a") | D36: Đ18.1: dưới 90% trong 30 ngày liên tục → nguy cơ mất khả năng chi trả
B37: Cảnh báo Đ18.1 (tại ngày chốt) | C37: =IF(NOT(ISNUMBER(C36)),"-",IF(C36<ThamSo!$E$74,"Dưới 90% — theo dõi chuỗi 30 ngày","Không"))
B39: IV. CƠ CẤU HQLA (tham khảo)
B40: Level 1 (sau hệ số) | C40: =HQLA!F6
B41: Level 2A (sau hệ số) | C41: =HQLA!F17
B42: Level 2B (sau hệ số) | C42: =HQLA!F21
B43: KĐC15% + KĐC40% (phần bị loại do trần) | C43: =HQLA!G27+HQLA!G28
B44: Tỷ trọng cấp 2 trong HQLA đủ điều kiện | C44: =IF(C24>0,(C41+C42-C43)/C24,"n/a") | D44: Chỉ để tham khảo; trần thực tế tính trên giá trị sau unwinding (KĐC).

Sheet ThamSo
A1: THAM SỐ — hệ số do TT50/2026/TT-NHNN ấn định
A2: Mỗi hệ số một ô, các sheet tính toán tham chiếu tới đây. Cột 'Dòng raw' là số dòng trong 01_sources/alm/TT50_2026_SBV/TT50_2026_SBV.md. Cột 'Đối chiếu (user)': ghi Y sau khi tự kiểm với văn bản gốc.
A4: Mã | B4: Nhóm | C4: Mục biểu mẫu | D4: Mô tả | E4: Hệ số | F4: Căn cứ TT50 | G4: Dòng raw | H4: Citation wiki | I4: Ghi chú | J4: Đối chiếu (user)
A5: HQ_L1 | B5: HQLA | C5: Bảng 3: 1.1–1.7 | D5: Hệ số thanh khoản tài sản cấp 1 | E5: 1 | F5: PL1.A.II.1 | G5: 1217 | H5: [[src-tt50-2026-nhnn#^pl1-a2]] | I5: NHNN có quyền yêu cầu hệ số thấp hơn (PL1.A.II.2)
A6: HQ_L2A | B6: HQLA | C6: Bảng 3: 2.1.1–2.1.3 | D6: Hệ số thanh khoản tài sản cấp 2A | E6: 0.85 | F6: PL1.A.III.1 | G6: 1263 | H6: [[src-tt50-2026-nhnn#^pl1-a3]]
A7: HQ_RMBS | B7: HQLA | C7: Bảng 3: 2.2.1 | D7: Hệ số thanh khoản RMBS đủ điều kiện (cấp 2B) | E7: 0.75 | F7: PL1.A.IV.3.a | G7: 1299 | H7: [[src-tt50-2026-nhnn#^pl1-a4]]
A8: HQ_CORP2B | B8: HQLA | C8: Bảng 3: 2.2.2 | D8: Hệ số thanh khoản chứng khoán nợ DN từ BBB- (cấp 2B) | E8: 0.5 | F8: PL1.A.IV.3.b | G8: 1317 | H8: [[src-tt50-2026-nhnn#^pl1-a4]]
A9: HQ_SOV2B | B9: HQLA | C9: Bảng 3: 2.2.3 | D9: Hệ số thanh khoản chứng khoán Chính phủ/NHTW nước ngoài từ BBB- (cấp 2B) | E9: 0.5 | F9: PL1.A.IV.3.c | G9: 1327 | H9: [[src-tt50-2026-nhnn#^pl1-a4]]
A10: HQ_EQ2B | B10: HQLA | C10: Bảng 3: 2.2.4 | D10: Hệ số thanh khoản cổ phiếu phổ thông đủ điều kiện (cấp 2B) | E10: 0.5 | F10: PL1.A.IV.3.d | G10: 1337 | H10: [[src-tt50-2026-nhnn#^pl1-a4]]
A11: HQ_BR2B | B11: HQLA | C11: Bảng 3: 2.2.5 | D11: Hệ số thanh khoản tài sản cấp 2B của chi nhánh ở nước ngoài | E11: 0.5 | F11: PL1.A.IV.3.đ | G11: 1378 | H11: chưa có claim trong source note | I11: Biểu mẫu ghi 'Theo từng loại'. Giá trị 50% là giữ chỗ — NGÂN HÀNG NHẬP theo loại tài sản (75% nếu RMBS).
A12: KDC_1585 | B12: HQLA | C12: Bảng 3: 3 | D12: Hệ số 15/85 trong KĐC15% | E12: 0.17647059 | F12: PL1.A.I.2 | G12: 1143 | H12: [[src-tt50-2026-nhnn#^pl1-a1]] | I12: Trần cấp 2B ≈ 15% HQLA
A13: KDC_1560 | B13: HQLA | C13: Bảng 3: 3 | D13: Hệ số 15/60 trong KĐC15% | E13: 0.25 | F13: PL1.A.I.2 | G13: 1143 | H13: [[src-tt50-2026-nhnn#^pl1-a1]]
A14: KDC_23 | B14: HQLA | C14: Bảng 3: 4 | D14: Hệ số 2/3 trong KĐC40% | E14: 0.66666667 | F14: PL1.A.I.3 | G14: 1145 | H14: [[src-tt50-2026-nhnn#^pl1-a1]] | I14: Trần cấp 2 ≈ 40% HQLA
A15: HM_MAX | B15: HQLA | C15: Bảng 3: 5.2 | D15: Trần hạn mức ngân hàng mẹ (tổng) / HQLA phải đáp ứng | E15: 0.5 | F15: PL1.A.I.5 | G15: 1187 | H15: [[src-tt50-2026-nhnn#^pl1-a1-4]] | I15: Chỉ áp dụng chi nhánh NHNNg
A16: HM_NOBACK | B16: HQLA | C16: Bảng 3: 5.2.2 | D16: Trần hạn mức không đối ứng HQLA cấp 1 / HQLA phải đáp ứng | E16: 0.4 | F16: PL1.A.I.5.b | G16: 1199 | H16: [[src-tt50-2026-nhnn#^pl1-a1-4]] | I16: Chỉ áp dụng chi nhánh NHNNg
A17: O_RET_S | B17: Dòng ra | C17: Bảng 6: 1.1 | D17: Tiền gửi bán lẻ ổn định | E17: 0.05 | F17: PL1.B.II.2.2 | G17: 1460 | H17: [[src-tt50-2026-nhnn#^pl1-b2]]
A18: O_RET_L | B18: Dòng ra | C18: Bảng 6: 1.2 | D18: Tiền gửi bán lẻ kém ổn định | E18: 0.1 | F18: PL1.B.II.3.2 | G18: 1466 | H18: [[src-tt50-2026-nhnn#^pl1-b2]] | I18: Gồm tiền gửi ngoại tệ và phần vượt hạn mức BHTG
A19: O_SME_S | B19: Dòng ra | C19: Bảng 6: 2.1.1 | D19: Tiền gửi DNNVV đủ điều kiện — ổn định | E19: 0.05 | F19: PL1.B.III.2.2.a(iii) | G19: 1502 | H19: [[src-tt50-2026-nhnn#^pl1-b3]] | I19: Như tiền gửi bán lẻ ổn định
A20: O_SME_L | B20: Dòng ra | C20: Bảng 6: 2.1.2 | D20: Tiền gửi DNNVV đủ điều kiện — kém ổn định | E20: 0.1 | F20: PL1.B.III.2.2.a(iii) | G20: 1502 | H20: [[src-tt50-2026-nhnn#^pl1-b3]] | I20: Như tiền gửi bán lẻ kém ổn định
A21: O_OPD | B21: Dòng ra | C21: Bảng 6: 2.2 | D21: Tiền gửi hoạt động | E21: 0.25 | F21: PL1.B.III.2.3.a(ii) | G21: 1526 | H21: [[src-tt50-2026-nhnn#^pl1-b3]] | I21: Chỉ phần không vượt mức yêu cầu; không xác định được phần vượt thì toàn bộ không đủ điều kiện (1592)
A22: O_CORP | B22: Dòng ra | C22: Bảng 6: 2.3 | D22: Nguồn vốn từ DN, Chính phủ, NHTW, PSE, tổ chức tài chính quốc tế | E22: 0.4 | F22: PL1.B.III.2.4.b | G22: 1604 | H22: [[src-tt50-2026-nhnn#^pl1-b3]]
A23: O_UNS_OTH | B23: Dòng ra | C23: Bảng 6: 2.4 | D23: Nguồn vốn không có bảo đảm khác | E23: 1 | F23: PL1.B.III.2.5.b | G23: 1610 | H23: [[src-tt50-2026-nhnn#^pl1-b3]]
A24: O_SEC_L1 | B24: Dòng ra | C24: Bảng 6: 3.1 | D24: Có bảo đảm bằng HQLA cấp 1 / giao dịch với NHNN | E24: 0 | F24: PL1.B.III.3.2.2.a | G24: 1636 | H24: [[src-tt50-2026-nhnn#^pl1-b3-3]]
A25: O_SEC_L2A | B25: Dòng ra | C25: Bảng 6: 3.2 | D25: Có bảo đảm bằng HQLA cấp 2A | E25: 0.15 | F25: PL1.B.III.3.2.2.b | G25: 1637 | H25: [[src-tt50-2026-nhnn#^pl1-b3-3]]
A26: O_SEC_GOV | B26: Dòng ra | C26: Bảng 6: 3.3 | D26: Có bảo đảm bằng tài sản khác, đối tác Chính phủ/KBNN/UBND/NHCS/VAMC/DATC/BHTG/BHXH/TCTC quốc tế | E26: 0.25 | F26: PL1.B.III.3.2.2.c | G26: 1638 | H26: [[src-tt50-2026-nhnn#^pl1-b3-3]]
A27: O_SEC_RMBS | B27: Dòng ra | C27: Bảng 6: 3.4 | D27: Có bảo đảm bằng RMBS cấp 2B | E27: 0.25 | F27: PL1.B.III.3.2.2.d | G27: 1639 | H27: [[src-tt50-2026-nhnn#^pl1-b3-3]]
A28: O_SEC_2B | B28: Dòng ra | C28: Bảng 6: 3.5 | D28: Có bảo đảm bằng HQLA cấp 2B khác | E28: 0.5 | F28: PL1.B.III.3.2.2.đ | G28: 1640 | H28: [[src-tt50-2026-nhnn#^pl1-b3-3]]
A29: O_SEC_OTH | B29: Dòng ra | C29: Bảng 6: 3.6 | D29: Có bảo đảm bằng tài sản tài chính khác | E29: 1 | F29: PL1.B.III.3.2.2.e | G29: 1641 | H29: [[src-tt50-2026-nhnn#^pl1-b3-3]]
A30: O_COLVAL | B30: Dòng ra | C30: Bảng 6: 4.1 | D30: Khả năng thay đổi giá trị tài sản bảo đảm (không phải HQLA cấp 1) | E30: 0.2 | F30: PL1.B.IV.2.2.b | G30: 1685 | H30: [[src-tt50-2026-nhnn#^pl1-b4]] | I30: Giá trị TSBĐ = danh nghĩa × hệ số thanh khoản (cấp 2 theo Mục III/IV; tài sản khác 25%)
A31: O_DOWNGR | B31: Dòng ra | C31: Bảng 6: 4.2 | D31: Hạ bậc tín nhiệm tối đa 3 bậc | E31: 1 | F31: PL1.B.IV.2.1.b | G31: 1679 | H31: [[src-tt50-2026-nhnn#^pl1-b4]]
A32: O_EXCOL | B32: Dòng ra | C32: Bảng 6: 4.3 | D32: TSBĐ dư thừa không tách biệt, đối tác có quyền thu hồi | E32: 1 | F32: PL1.B.IV.2.3.b | G32: 1701 | H32: chưa có claim trong source note
A33: O_UNCALL | B33: Dòng ra | C33: Bảng 6: 4.4 | D33: TSBĐ phải ký quỹ nhưng đối tác chưa yêu cầu | E33: 1 | F33: PL1.B.IV.2.4 | G33: 1705 | H33: chưa có claim trong source note
A34: O_MTM | B34: Dòng ra | C34: Bảng 6: 4.5 | D34: Thay đổi định giá thị trường (dòng ký quỹ ròng lớn nhất 30 ngày trong 24 tháng) | E34: 1 | F34: PL1.B.IV.2.5.b | G34: 1721 | H34: [[src-tt50-2026-nhnn#^pl1-b4]]
A35: O_F_RET | B35: Dòng ra | C35: Bảng 6: 5.1.1 | D35: Hạn mức chưa sử dụng — cá nhân, DNNVV (tín dụng và thanh khoản) | E35: 0.05 | F35: PL1.B.V.1.5.a | G35: 1748 | H35: [[src-tt50-2026-nhnn#^pl1-b5]]
A36: O_F_CORP_C | B36: Dòng ra | C36: Bảng 6: 5.1.2 | D36: Hạn mức tín dụng — DN không phải TCTC | E36: 0.1 | F36: PL1.B.V.1.5.b | G36: 1749 | H36: [[src-tt50-2026-nhnn#^pl1-b5]]
A37: O_F_CORP_L | B37: Dòng ra | C37: Bảng 6: 5.1.2 | D37: Hạn mức thanh khoản — DN không phải TCTC | E37: 0.3 | F37: PL1.B.V.1.5.b | G37: 1749 | H37: [[src-tt50-2026-nhnn#^pl1-b5]]
A38: O_F_GOV_C | B38: Dòng ra | C38: Bảng 6: 5.1.3 | D38: Hạn mức tín dụng — Chính phủ, NHTW, PSE, KBNN, UBND, BHTG, TCTC quốc tế | E38: 0.1 | F38: PL1.B.V.1.5.c | G38: 1750 | H38: [[src-tt50-2026-nhnn#^pl1-b5]] | I38: Biểu mẫu Bảng 6 để trống ô hệ số; lấy theo Bảng 5 điểm c
A39: O_F_GOV_L | B39: Dòng ra | C39: Bảng 6: 5.1.3 | D39: Hạn mức thanh khoản — Chính phủ, NHTW, PSE, KBNN, UBND, BHTG, TCTC quốc tế | E39: 0.3 | F39: PL1.B.V.1.5.c | G39: 1750 | H39: [[src-tt50-2026-nhnn#^pl1-b5]] | I39: Như trên
A40: O_F_CI | B40: Dòng ra | C40: Bảng 6: 5.1.4 | D40: Hạn mức chưa sử dụng — TCTD, chi nhánh NHNNg | E40: 0.4 | F40: PL1.B.V.1.5.d | G40: 1751 | H40: [[src-tt50-2026-nhnn#^pl1-b5]]
A41: O_F_FI_C | B41: Dòng ra | C41: Bảng 6: 5.1.5 | D41: Hạn mức tín dụng — tổ chức tài chính khác | E41: 0.4 | F41: PL1.B.V.1.5.đ | G41: 1752 | H41: [[src-tt50-2026-nhnn#^pl1-b5]]
...

Sheet HQLA
A1: HQLA ĐỦ ĐIỀU KIỆN — TT50 PL1 Bảng 3
A2: Đơn vị: tỷ đồng. Ô nền vàng chữ xanh = nhập liệu (SỐ LIỆU MINH HOẠ). Cột (1): số dư đủ điều kiện theo giá thị trường. Cột (2): giá trị sau unwinding giao dịch có bảo đảm/repo/reverse repo đáo hạn trong 30 ngày — để trống nếu không có giao dịch cần đảo ngược, khi đó (5) lấy theo (1) (PL1.A.I.c).
A4: Mục | B4: Các loại tài sản | C4: Số dư | D4: Giá trị điều chỉnh | E4: Hệ số thanh khoản | F4: Giá trị sau khi nhân với hệ số thanh khoản | G4: Giá trị điều chỉnh sau khi nhân với hệ số thanh khoản | H4: Nội dung hướng dẫn tại PL1 | I4: Căn cứ / citation
C5: (1) | D5: (2) | E5: (3) | F5: (4)=(1)x(3) | G5: (5)=(2)x(3)
A6: 1 | B6: Tài sản cấp 1 = ∑(1.1÷1.7) | C6: =C7+C8+C9+C10+C13+C14+C15 | F6: =F7+F8+F9+F10+F13+F14+F15 | G6: =G7+G8+G9+G10+G13+G14+G15
A7: 1.1 | B7: Tiền mặt | C7: 3200 | E7: =ThamSo!$E$5 | F7: =C7*E7 | G7: =IF(D7="",C7,D7)*E7 | H7: Điểm 3a Mục II Phần A | I7: PL1.A.II.1 (raw dòng 1217); [[src-tt50-2026-nhnn#^pl1-a2]]
A8: 1.2 | B8: Tiền gửi (bao gồm cả tiền gửi dự trữ bắt buộc) tại Ngân hàng Nhà nước | C8: 14500 | D8: 11500 | E8: =ThamSo!$E$5 | F8: =C8*E8 | G8: =IF(D8="",C8,D8)*E8 | H8: Điểm 3b Mục II Phần A | I8: PL1.A.II.1 (raw dòng 1217); [[src-tt50-2026-nhnn#^pl1-a2]]
A9: 1.3 | B9: Chứng khoán của Chính phủ, NHTW các nước khác, tổ chức công lập của Chính phủ và tổ chức tài chính quốc tế đáp ứng điều kiện và chứng khoán được đảm bảo bởi các đối tượng này | C9: 0 | E9: =ThamSo!$E$5 | F9: =C9*E9 | G9: =IF(D9="",C9,D9)*E9 | H9: Điểm 3c Mục II Phần A | I9: PL1.A.II.1 (raw dòng 1217); [[src-tt50-2026-nhnn#^pl1-a2]]
A10: 1.4 | B10: Công cụ nợ, trái phiếu Chính phủ Việt Nam hoặc Ngân hàng Nhà nước = (1.4.1) + (1.4.2) | C10: =C11+C12 | F10: =F11+F12 | G10: =G11+G12
A11: 1.4.1 | B11: Công cụ nợ bằng VNĐ | C11: 26000 | E11: =ThamSo!$E$5 | F11: =C11*E11 | G11: =IF(D11="",C11,D11)*E11 | H11: Điểm 3d Mục II Phần A | I11: PL1.A.II.1 (raw dòng 1217); [[src-tt50-2026-nhnn#^pl1-a2]]
A12: 1.4.2 | B12: Công cụ nợ bằng ngoại tệ | C12: 800 | E12: =ThamSo!$E$5 | F12: =C12*E12 | G12: =IF(D12="",C12,D12)*E12 | H12: Điểm 3đ Mục II Phần A | I12: PL1.A.II.1 (raw dòng 1217); [[src-tt50-2026-nhnn#^pl1-a2]]
A13: 1.5 | B13: Trái phiếu được Chính phủ bảo lãnh thanh toán 100% giá trị gốc, lãi khi đến hạn; trái phiếu chính quyền địa phương | C13: 1500 | E13: =ThamSo!$E$5 | F13: =C13*E13 | G13: =IF(D13="",C13,D13)*E13 | H13: Điểm 3e Mục II Phần A | I13: PL1.A.II.1 (raw dòng 1217); [[src-tt50-2026-nhnn#^pl1-a2]]
A14: 1.6 | B14: Tài sản trong danh mục HQLA của chi nhánh ở nước ngoài của ngân hàng thương mại | C14: 0 | E14: =ThamSo!$E$5 | F14: =C14*E14 | G14: =IF(D14="",C14,D14)*E14 | H14: Điểm 3g Mục II Phần A | I14: PL1.A.II.1 (raw dòng 1217); [[src-tt50-2026-nhnn#^pl1-a2]]
A15: 1.7 | B15: Công cụ nợ, trái phiếu của Chính phủ và NHTW của quốc gia mà chi nhánh ở nước ngoài của NHTM đặt trụ sở (tối đa bằng dòng tiền ra ròng của chi nhánh đó) | C15: 0 | E15: =ThamSo!$E$5 | F15: =C15*E15 | G15: =IF(D15="",C15,D15)*E15 | H15: Điểm 3h Mục II Phần A | I15: PL1.A.II.1 (raw dòng 1217); [[src-tt50-2026-nhnn#^pl1-a2]]
A16: 2 | B16: Tài sản cấp 2 | C16: =C17+C21 | F16: =F17+F21 | G16: =G17+G21
A17: 2.1 | B17: Tài sản cấp 2A = ∑(2.1.1÷2.1.3) | C17: =C18+C19+C20 | F17: =F18+F19+F20 | G17: =G18+G19+G20
A18: 2.1.1 | B18: Chứng khoán của Chính phủ, NHTW, tổ chức tài chính quốc tế và tổ chức công lập của Chính phủ đủ điều kiện với hệ số rủi ro tối đa 20% | C18: 0 | E18: =ThamSo!$E$6 | F18: =C18*E18 | G18: =IF(D18="",C18,D18)*E18 | H18: Điểm 3a Mục III Phần A | I18: PL1.A.III.1 (raw dòng 1263); [[src-tt50-2026-nhnn#^pl1-a3]]
A19: 2.1.2 | B19: Chứng khoán nợ của doanh nghiệp đủ điều kiện xếp hạng từ AA- trở lên | C19: 2400 | D19: 5400 | E19: =ThamSo!$E$6 | F19: =C19*E19 | G19: =IF(D19="",C19,D19)*E19 | H19: Điểm 3b Mục III Phần A | I19: PL1.A.III.1 (raw dòng 1263); [[src-tt50-2026-nhnn#^pl1-a3]]
A20: 2.1.3 | B20: Tài sản trong danh mục HQLA của chi nhánh ở nước ngoài của NHTM | C20: 0 | E20: =ThamSo!$E$6 | F20: =C20*E20 | G20: =IF(D20="",C20,D20)*E20 | H20: Điểm 3c Mục III Phần A | I20: PL1.A.III.1 (raw dòng 1263); [[src-tt50-2026-nhnn#^pl1-a3]]
A21: 2.2 | B21: Tài sản cấp 2B = ∑(2.2.1÷2.2.5) | C21: =C22+C23+C24+C25+C26 | F21: =F22+F23+F24+F25+F26 | G21: =G22+G23+G24+G25+G26
A22: 2.2.1 | B22: RMBS đủ điều kiện | C22: 0 | E22: =ThamSo!$E$7 | F22: =C22*E22 | G22: =IF(D22="",C22,D22)*E22 | H22: Điểm 3a Mục IV Phần A | I22: PL1.A.IV.3.a (raw dòng 1299); [[src-tt50-2026-nhnn#^pl1-a4]]
A23: 2.2.2 | B23: Chứng khoán nợ của doanh nghiệp đủ điều kiện xếp hạng từ BBB- trở lên | C23: 2600 | E23: =ThamSo!$E$8 | F23: =C23*E23 | G23: =IF(D23="",C23,D23)*E23 | H23: Điểm 3b Mục IV Phần A | I23: PL1.A.IV.3.b (raw dòng 1317); [[src-tt50-2026-nhnn#^pl1-a4]]
A24: 2.2.3 | B24: Chứng khoán của Chính phủ, NHTW, PSE hoặc tổ chức tài chính quốc tế đủ điều kiện, xếp hạng BBB- trở lên nhưng không thuộc cấp 1 hoặc 2A | C24: 0 | E24: =ThamSo!$E$9 | F24: =C24*E24 | G24: =IF(D24="",C24,D24)*E24 | H24: Điểm 3c Mục IV Phần A | I24: PL1.A.IV.3.c (raw dòng 1327); [[src-tt50-2026-nhnn#^pl1-a4]]
A25: 2.2.4 | B25: Cổ phiếu phổ thông đủ điều kiện | C25: 900 | E25: =ThamSo!$E$10 | F25: =C25*E25 | G25: =IF(D25="",C25,D25)*E25 | H25: Điểm 3d Mục IV Phần A | I25: PL1.A.IV.3.d (raw dòng 1337); [[src-tt50-2026-nhnn#^pl1-a4]]
A26: 2.2.5 | B26: Tài sản trong danh mục HQLA của chi nhánh ở nước ngoài của NHTM (hệ số theo từng loại) | C26: 0 | E26: =ThamSo!$E$11 | F26: =C26*E26 | G26: =IF(D26="",C26,D26)*E26 | H26: Điểm 3đ Mục IV Phần A | I26: PL1.A.IV.3.đ (raw dòng 1378); chưa có claim trong source note
A27: 3 | B27: KĐC15% | G27: =MAX(G21-ThamSo!$E$12*(G6+G17),G21-ThamSo!$E$13*G6,0) | H27: Điểm 2 Mục I Phần A | I27: PL1.A.I.2 (raw dòng 1143); [[src-tt50-2026-nhnn#^pl1-a1]]
A28: 4 | B28: KĐC40% | G28: =MAX(G17+G21-G27-ThamSo!$E$14*G6,0) | H28: Điểm 3 Mục I Phần A | I28: PL1.A.I.3 (raw dòng 1145); [[src-tt50-2026-nhnn#^pl1-a1]]
A29: 5 | B29: Hạn mức = (5.1) + (5.2) | G29: =G30+G31
A30: 5.1 | B30: Hạn mức chưa sử dụng được thiết lập trong giao dịch với Ngân hàng Nhà nước (bảo đảm bằng HQLA cấp 1) | C30: 0 | G30: =C30 | H30: Điểm 4 Mục I Phần A | I30: PL1.A.I.4 (raw dòng 1185); [[src-tt50-2026-nhnn#^pl1-a1-4]]
A31: 5.2 | B31: Hạn mức chưa sử dụng của ngân hàng mẹ (chỉ chi nhánh NHNNg) = (5.2.1) + (5.2.2), sau trần | G31: =MIN(G32+G33,ThamSo!$E$15*KetQua!$C$29) | H31: Điểm 5 Mục I Phần A | I31: PL1.A.I.5 (raw dòng 1187); [[src-tt50-2026-nhnn#^pl1-a1-4]]
A32: 5.2.1 | B32: Hạn mức cam kết trên cơ sở đối ứng bởi một danh mục HQLA cấp 1 | C32: 0 | G32: =C32 | H32: Điểm 5a Mục I Phần A
A33: 5.2.2 | B33: Hạn mức cam kết không hủy ngang không được đối ứng bởi danh mục HQLA cấp 1 (trần 40%) | C33: 0 | G33: =MIN(C33,ThamSo!$E$16*KetQua!$C$29) | H33: Điểm 5b Mục I Phần A | I33: PL1.A.I.5.b (raw dòng 1199); [[src-tt50-2026-nhnn#^pl1-a1-4]]
A34: Giá trị HQLA đủ điều kiện = Level 1 + Level 2A + Level 2B + Hạn mức (Mục 5) – KĐC15% (Mục 3) – KĐC40% (Mục 4) | G34: =F6+F17+F21+G29-G27-G28 | I34: PL1.A.I.1 (raw dòng 1141); [[src-tt50-2026-nhnn#^pl1-a1]]

Sheet DongTienRa
A1: DÒNG TIỀN RA — TT50 PL1 Bảng 6
A2: Đơn vị: tỷ đồng. Ô nền vàng chữ xanh = nhập liệu. Số đang có là SỐ LIỆU MINH HOẠ, thay bằng số liệu thật. Cột (1)–(4): số dư đủ điều kiện phân theo thời gian đến hạn theo hợp đồng/dự kiến.
A4: Mục | B4: Dòng tiền ra | C4: Ngày tiếp theo | D4: Từ ngày 2 đến ngày 7 | E4: Từ ngày 8 đến ngày 14 | F4: Từ ngày 15 đến ngày 30 | G4: Tổng | H4: Hệ số rút tiền | I4: Giá trị dòng tiền ra theo mức độ rủi ro | J4: Nội dung hướng dẫn tại PL1 | K4: Căn cứ / citation
C5: (1) | D5: (2) | E5: (3) | F5: (4) | G5: (5)=∑[(1)÷(4)] | H5: (6) | I5: (7)=(5)x(6)
A6: 1 | B6: Tiền gửi bán lẻ | C6: =C7+C8 | D6: =D7+D8 | E6: =E7+E8 | F6: =F7+F8 | G6: =G7+G8 | I6: =I7+I8
A7: 1.1 | B7: Tiền gửi ổn định | C7: 1200 | D7: 2600 | E7: 3100 | F7: 9100 | G7: =SUM(C7:F7) | H7: =ThamSo!$E$17 | I7: =G7*H7 | J7: Khoản 2 Mục II Phần B | K7: PL1.B.II.2.2 (raw dòng 1460); [[src-tt50-2026-nhnn#^pl1-b2]]
A8: 1.2 | B8: Tiền gửi kém ổn định | C8: 2400 | D8: 4800 | E8: 5600 | F8: 15200 | G8: =SUM(C8:F8) | H8: =ThamSo!$E$18 | I8: =G8*H8 | J8: Khoản 3 Mục II Phần B | K8: PL1.B.II.3.2 (raw dòng 1466); [[src-tt50-2026-nhnn#^pl1-b2]]
A9: 2 | B9: Nguồn vốn bán buôn không có bảo đảm | C9: =C10+C13+C14+C15 | D9: =D10+D13+D14+D15 | E9: =E10+E13+E14+E15 | F9: =F10+F13+F14+F15 | G9: =G10+G13+G14+G15 | I9: =I10+I13+I14+I15
A10: 2.1 | B10: Tiền gửi từ khách hàng doanh nghiệp nhỏ và vừa đủ điều kiện | C10: =C11+C12 | D10: =D11+D12 | E10: =E11+E12 | F10: =F11+F12 | G10: =G11+G12 | I10: =I11+I12
A11: 2.1.1 | B11: Tiền gửi ổn định | C11: 150 | D11: 300 | E11: 350 | F11: 900 | G11: =SUM(C11:F11) | H11: =ThamSo!$E$19 | I11: =G11*H11 | J11: Khoản 2.2 Mục III Phần B và khoản 2 Mục II Phần B | K11: PL1.B.III.2.2.a(iii) (raw dòng 1502); [[src-tt50-2026-nhnn#^pl1-b3]]
A12: 2.1.2 | B12: Tiền gửi kém ổn định | C12: 300 | D12: 600 | E12: 700 | F12: 1800 | G12: =SUM(C12:F12) | H12: =ThamSo!$E$20 | I12: =G12*H12 | J12: Khoản 2.2 Mục III Phần B và khoản 3 Mục II Phần B | K12: PL1.B.III.2.2.a(iii) (raw dòng 1502); [[src-tt50-2026-nhnn#^pl1-b3]]
A13: 2.2 | B13: Tiền gửi hoạt động | C13: 1500 | D13: 0 | E13: 0 | F13: 0 | G13: =SUM(C13:F13) | H13: =ThamSo!$E$21 | I13: =G13*H13 | J13: Khoản 2.3 Mục III Phần B | K13: PL1.B.III.2.3.a(ii) (raw dòng 1526); [[src-tt50-2026-nhnn#^pl1-b3]]
A14: 2.3 | B14: Nguồn vốn từ doanh nghiệp và Chính phủ, ngân hàng trung ương, tổ chức công lập của Chính phủ và tổ chức tài chính quốc tế | C14: 5000 | D14: 6000 | E14: 7000 | F14: 15000 | G14: =SUM(C14:F14) | H14: =ThamSo!$E$22 | I14: =G14*H14 | J14: Khoản 2.4 Mục III Phần B | K14: PL1.B.III.2.4.b (raw dòng 1604); [[src-tt50-2026-nhnn#^pl1-b3]]
A15: 2.4 | B15: Nguồn vốn không có bảo đảm khác | C15: 6000 | D15: 7000 | E15: 5000 | F15: 8000 | G15: =SUM(C15:F15) | H15: =ThamSo!$E$23 | I15: =G15*H15 | J15: Khoản 2.5 Mục III Phần B | K15: PL1.B.III.2.5.b (raw dòng 1610); [[src-tt50-2026-nhnn#^pl1-b3]]
A16: 3 | B16: Nguồn vốn bán buôn có bảo đảm | C16: =C17+C18+C19+C20+C21+C22 | D16: =D17+D18+D19+D20+D21+D22 | E16: =E17+E18+E19+E20+E21+E22 | F16: =F17+F18+F19+F20+F21+F22 | G16: =G17+G18+G19+G20+G21+G22 | I16: =I17+I18+I19+I20+I21+I22
A17: 3.1 | B17: Nguồn vốn được đảm bảo bằng HQLA cấp 1 hoặc nguồn vốn được bảo đảm trong giao dịch với Ngân hàng Nhà nước | C17: 2000 | D17: 1500 | E17: 0 | F17: 0 | G17: =SUM(C17:F17) | H17: =ThamSo!$E$24 | I17: =G17*H17 | J17: Khoản 3.2.2a Mục III Phần B | K17: PL1.B.III.3.2.2.a (raw dòng 1636); [[src-tt50-2026-nhnn#^pl1-b3-3]]
A18: 3.2 | B18: Nguồn vốn được đảm bảo bằng HQLA cấp 2A | C18: 0 | D18: 500 | E18: 0 | F18: 0 | G18: =SUM(C18:F18) | H18: =ThamSo!$E$25 | I18: =G18*H18 | J18: Khoản 3.2.2b Mục III Phần B | K18: PL1.B.III.3.2.2.b (raw dòng 1637); [[src-tt50-2026-nhnn#^pl1-b3-3]]
A19: 3.3 | B19: Nguồn vốn được đảm bảo bằng tài sản tài chính khác trong giao dịch với Chính phủ, Kho bạc Nhà nước… | C19: 0 | D19: 0 | E19: 0 | F19: 0 | G19: =SUM(C19:F19) | H19: =ThamSo!$E$26 | I19: =G19*H19 | J19: Khoản 3.2.2c Mục III Phần B | K19: PL1.B.III.3.2.2.c (raw dòng 1638); [[src-tt50-2026-nhnn#^pl1-b3-3]]
A20: 3.4 | B20: Nguồn vốn được bảo đảm bằng chứng khoán đảm bảo bằng thế chấp nhà ở (RMBS) đủ điều kiện thuộc cấp 2B | C20: 0 | D20: 0 | E20: 0 | F20: 0 | G20: =SUM(C20:F20) | H20: =ThamSo!$E$27 | I20: =G20*H20 | J20: Khoản 3.2.2d Mục III Phần B | K20: PL1.B.III.3.2.2.d (raw dòng 1639); [[src-tt50-2026-nhnn#^pl1-b3-3]]
A21: 3.5 | B21: Nguồn vốn được bảo đảm bằng các HQLA cấp 2B khác | C21: 0 | D21: 0 | E21: 0 | F21: 0 | G21: =SUM(C21:F21) | H21: =ThamSo!$E$28 | I21: =G21*H21 | J21: Khoản 3.2.2đ Mục III Phần B | K21: PL1.B.III.3.2.2.đ (raw dòng 1640); [[src-tt50-2026-nhnn#^pl1-b3-3]]
A22: 3.6 | B22: Nguồn vốn được đảm bảo bằng các tài sản tài chính khác | C22: 0 | D22: 0 | E22: 200 | F22: 0 | G22: =SUM(C22:F22) | H22: =ThamSo!$E$29 | I22: =G22*H22 | J22: Khoản 3.2.2e Mục III Phần B | K22: PL1.B.III.3.2.2.e (raw dòng 1641); [[src-tt50-2026-nhnn#^pl1-b3-3]]
A23: 4 | B23: Yêu cầu bổ sung | C23: =C24+C25+C26+C27+C28 | D23: =D24+D25+D26+D27+D28 | E23: =E24+E25+E26+E27+E28 | F23: =F24+F25+F26+F27+F28 | G23: =G24+G25+G26+G27+G28 | I23: =I24+I25+I26+I27+I28
A24: 4.1 | B24: Nhu cầu thanh khoản do khả năng thay đổi giá trị tài sản bảo đảm | C24: 0 | D24: 0 | E24: 0 | F24: 400 | G24: =SUM(C24:F24) | H24: =ThamSo!$E$30 | I24: =G24*H24 | J24: Khoản 2.2 Mục IV Phần B | K24: PL1.B.IV.2.2.b (raw dòng 1685); [[src-tt50-2026-nhnn#^pl1-b4]]
A25: 4.2 | B25: Dòng tiền ra bổ sung khi bị hạ bậc xếp hạng tín nhiệm | C25: 0 | D25: 0 | E25: 0 | F25: 0 | G25: =SUM(C25:F25) | H25: =ThamSo!$E$31 | I25: =G25*H25 | J25: Khoản 2.1 Mục IV Phần B | K25: PL1.B.IV.2.1.b (raw dòng 1679); [[src-tt50-2026-nhnn#^pl1-b4]]
A26: 4.3 | B26: Dòng tiền ra bổ sung do bên đối tác có quyền yêu cầu thu hồi theo thỏa thuận | C26: 0 | D26: 0 | E26: 0 | F26: 0 | G26: =SUM(C26:F26) | H26: =ThamSo!$E$32 | I26: =G26*H26 | J26: Khoản 2.3 Mục IV Phần B | K26: PL1.B.IV.2.3.b (raw dòng 1701); chưa có claim trong source note
A27: 4.4 | B27: Dòng tiền ra bổ sung do phải ký quỹ theo thỏa thuận nhưng đối tác chưa yêu cầu ký quỹ | C27: 0 | D27: 0 | E27: 0 | F27: 0 | G27: =SUM(C27:F27) | H27: =ThamSo!$E$33 | I27: =G27*H27 | J27: Khoản 2.4 Mục IV Phần B | K27: PL1.B.IV.2.4 (raw dòng 1705); chưa có claim trong source note
A28: 4.5 | B28: Dòng tiền ra bổ sung do thay đổi định giá thị trường | C28: 0 | D28: 0 | E28: 0 | F28: 350 | G28: =SUM(C28:F28) | H28: =ThamSo!$E$34 | I28: =G28*H28 | J28: Khoản 2.5 Mục IV Phần B | K28: PL1.B.IV.2.5.b (raw dòng 1721); [[src-tt50-2026-nhnn#^pl1-b4]]
A29: 5 | B29: Dòng tiền ra từ cam kết ngoại bảng | C29: =C30+C43+C47 | D29: =D30+D43+D47 | E29: =E30+E43+E47 | F29: =F30+F43+F47 | G29: =G30+G43+G47 | I29: =I30+I43+I47
A30: 5.1 | B30: Hạn mức cam kết chưa sử dụng | C30: =C31+C32+C35+C38+C39+C42 | D30: =D31+D32+D35+D38+D39+D42 | E30: =E31+E32+E35+E38+E39+E42 | F30: =F31+F32+F35+F38+F39+F42 | G30: =G31+G32+G35+G38+G39+G42 | I30: =I31+I32+I35+I38+I39+I42 | J30: Khoản 1 Mục V Phần B
A31: 5.1.1 | B31: Đối với khách hàng bán lẻ và doanh nghiệp nhỏ và vừa đủ điều kiện | C31: 0 | D31: 0 | E31: 0 | F31: 6000 | G31: =SUM(C31:F31) | H31: =ThamSo!$E$35 | I31: =G31*H31 | J31: Khoản 1.5a Mục V Phần B | K31: PL1.B.V.1.5.a (raw dòng 1748); [[src-tt50-2026-nhnn#^pl1-b5]]
A32: 5.1.2 | B32: Doanh nghiệp không phải tổ chức tài chính | C32: =C33+C34 | D32: =D33+D34 | E32: =E33+E34 | F32: =F33+F34 | G32: =G33+G34 | I32: =I33+I34 | J32: Khoản 1.5b Mục V Phần B
A33: 5.1.2a | B33: – Hạn mức tín dụng | C33: 0 | D33: 0 | E33: 0 | F33: 12000 | G33: =SUM(C33:F33) | H33: =ThamSo!$E$36 | I33: =G33*H33 | J33: Khoản 1.5b Mục V Phần B | K33: PL1.B.V.1.5.b (raw dòng 1749); [[src-tt50-2026-nhnn#^pl1-b5]]
A34: 5.1.2b | B34: – Hạn mức thanh khoản | C34: 0 | D34: 0 | E34: 0 | F34: 800 | G34: =SUM(C34:F34) | H34: =ThamSo!$E$37 | I34: =G34*H34 | J34: Khoản 1.5b Mục V Phần B | K34: PL1.B.V.1.5.b (raw dòng 1749); [[src-tt50-2026-nhnn#^pl1-b5]]
A35: 5.1.3 | B35: Chính phủ, ngân hàng trung ương, tổ chức tài chính quốc tế và tổ chức công lập của Chính phủ | C35: =C36+C37 | D35: =D36+D37 | E35: =E36+E37 | F35: =F36+F37 | G35: =G36+G37 | I35: =I36+I37 | J35: Khoản 1.5c Mục V Phần B
A36: 5.1.3a | B36: – Hạn mức tín dụng | C36: 0 | D36: 0 | E36: 0 | F36: 0 | G36: =SUM(C36:F36) | H36: =ThamSo!$E$38 | I36: =G36*H36 | J36: Khoản 1.5c Mục V Phần B | K36: PL1.B.V.1.5.c (raw dòng 1750); [[src-tt50-2026-nhnn#^pl1-b5]]
A37: 5.1.3b | B37: – Hạn mức thanh khoản | C37: 0 | D37: 0 | E37: 0 | F37: 0 | G37: =SUM(C37:F37) | H37: =ThamSo!$E$39 | I37: =G37*H37 | J37: Khoản 1.5c Mục V Phần B | K37: PL1.B.V.1.5.c (raw dòng 1750); [[src-tt50-2026-nhnn#^pl1-b5]]
A38: 5.1.4 | B38: Tổ chức tín dụng, chi nhánh ngân hàng nước ngoài | C38: 0 | D38: 0 | E38: 0 | F38: 500 | G38: =SUM(C38:F38) | H38: =ThamSo!$E$40 | I38: =G38*H38 | J38: Khoản 1.5d Mục V Phần B | K38: PL1.B.V.1.5.d (raw dòng 1751); [[src-tt50-2026-nhnn#^pl1-b5]]
A39: 5.1.5 | B39: Tổ chức tài chính khác (bao gồm công ty chứng khoán, bảo hiểm, công ty quản lý quỹ) | C39: =C40+C41 | D39: =D40+D41 | E39: =E40+E41 | F39: =F40+F41 | G39: =G40+G41 | I39: =I40+I41 | J39: Khoản 1.5đ Mục V Phần B
A40: 5.1.5a | B40: – Hạn mức tín dụng | C40: 0 | D40: 0 | E40: 0 | F40: 0 | G40: =SUM(C40:F40) | H40: =ThamSo!$E$41 | I40: =G40*H40 | J40: Khoản 1.5đ Mục V Phần B | K40: PL1.B.V.1.5.đ (raw dòng 1752); [[src-tt50-2026-nhnn#^pl1-b5]]
A41: 5.1.5b | B41: – Hạn mức thanh khoản | C41: 0 | D41: 0 | E41: 0 | F41: 0 | G41: =SUM(C41:F41) | H41: =ThamSo!$E$42 | I41: =G41*H41 | J41: Khoản 1.5đ Mục V Phần B | K41: PL1.B.V.1.5.đ (raw dòng 1752); [[src-tt50-2026-nhnn#^pl1-b5]]
...

Sheet DongTienVao
A1: DÒNG TIỀN VÀO — TT50 PL1 Bảng 8
A2: Đơn vị: tỷ đồng. Ô nền vàng chữ xanh = nhập liệu. Số đang có là SỐ LIỆU MINH HOẠ, thay bằng số liệu thật. Cột (1)–(4): số dư đủ điều kiện phân theo thời gian đến hạn theo hợp đồng/dự kiến.
A4: Mục | B4: Dòng tiền vào | C4: Ngày tiếp theo | D4: Từ ngày 2 đến ngày 7 | E4: Từ ngày 8 đến ngày 14 | F4: Từ ngày 15 đến ngày 30 | G4: Tổng | H4: Hệ số thu tiền | I4: Giá trị dòng tiền vào theo mức độ rủi ro | J4: Nội dung hướng dẫn tại PL1 | K4: Căn cứ / citation
C5: (1) | D5: (2) | E5: (3) | F5: (4) | G5: (5)=∑[(1)÷(4)] | H5: (6) | I5: (7)=(5)x(6)
A6: 1 | B6: Khoản cấp tín dụng có bảo đảm bằng tài sản tài chính hoặc giao dịch mua lại đảo ngược (reverse repo) | C6: =C7+C8+C9+C12+C13 | D6: =D7+D8+D9+D12+D13 | E6: =E7+E8+E9+E12+E13 | F6: =F7+F8+F9+F12+F13 | G6: =G7+G8+G9+G12+G13 | I6: =I7+I8+I9+I12+I13
A7: 1.1 | B7: Tài sản cấp 1 | C7: 1000 | D7: 500 | E7: 0 | F7: 0 | G7: =SUM(C7:F7) | H7: =ThamSo!$E$55 | I7: =G7*H7 | J7: Khoản 2.1 và khoản 4a Mục II Phần C | K7: PL1.C.II.4.a (raw dòng 1900); [[src-tt50-2026-nhnn#^pl1-c2]]
A8: 1.2 | B8: Tài sản cấp 2A | C8: 0 | D8: 200 | E8: 0 | F8: 0 | G8: =SUM(C8:F8) | H8: =ThamSo!$E$56 | I8: =G8*H8 | J8: Khoản 2.2 và khoản 4b Mục II Phần C | K8: PL1.C.II.4.b (raw dòng 1901); [[src-tt50-2026-nhnn#^pl1-c2]]
A9: 1.3 | B9: Tài sản cấp 2B | C9: =C10+C11 | D9: =D10+D11 | E9: =E10+E11 | F9: =F10+F11 | G9: =G10+G11 | I9: =I10+I11
A10: 1.3.1 | B10: RMBS đủ điều kiện | C10: 0 | D10: 0 | E10: 0 | F10: 0 | G10: =SUM(C10:F10) | H10: =ThamSo!$E$57 | I10: =G10*H10 | J10: Khoản 2.2 và khoản 4c Mục II Phần C | K10: PL1.C.II.4.c (raw dòng 1902); [[src-tt50-2026-nhnn#^pl1-c2]]
A11: 1.3.2 | B11: Tài sản cấp 2B khác | C11: 0 | D11: 0 | E11: 0 | F11: 0 | G11: =SUM(C11:F11) | H11: =ThamSo!$E$58 | I11: =G11*H11 | J11: Khoản 2.2 và khoản 4d Mục II Phần C | K11: PL1.C.II.4.d (raw dòng 1903); [[src-tt50-2026-nhnn#^pl1-c2]]
A12: 1.4 | B12: Khoản cho vay ký quỹ | C12: 0 | D12: 0 | E12: 0 | F12: 0 | G12: =SUM(C12:F12) | H12: =ThamSo!$E$59 | I12: =G12*H12 | J12: Khoản 3 và khoản 4đ Mục II Phần C | K12: PL1.C.II.4.đ (raw dòng 1904); [[src-tt50-2026-nhnn#^pl1-c2]]
A13: 1.5 | B13: Các tài sản tài chính khác | C13: 0 | D13: 0 | E13: 300 | F13: 0 | G13: =SUM(C13:F13) | H13: =ThamSo!$E$60 | I13: =G13*H13 | J13: Khoản 2.3 và khoản 4e Mục II Phần C | K13: PL1.C.II.4.e (raw dòng 1905); [[src-tt50-2026-nhnn#^pl1-c2]]
A14: 2 | B14: Hạn mức tín dụng hoặc thanh khoản được cung cấp cho ngân hàng báo cáo | C14: 0 | D14: 0 | E14: 0 | F14: 0 | G14: =SUM(C14:F14) | H14: =ThamSo!$E$61 | I14: =G14*H14 | J14: Mục III Phần C | K14: PL1.C.III (raw dòng 1911); [[src-tt50-2026-nhnn#^pl1-c1]]
A15: 3 | B15: Tiền gửi hoạt động | C15: =C16+C17 | D15: =D16+D17 | E15: =E16+E17 | F15: =F16+F17 | G15: =G16+G17 | I15: =I16+I17 | J15: Khoản 8 Mục IV Phần C
A16: 3.1 | B16: Tiền gửi hoạt động tại các tổ chức tài chính khác | C16: 800 | D16: 0 | E16: 0 | F16: 0 | G16: =SUM(C16:F16) | H16: =ThamSo!$E$62 | I16: =G16*H16 | J16: Khoản 8a Mục IV Phần C | K16: PL1.C.IV.8.a (raw dòng 1949); [[src-tt50-2026-nhnn#^pl1-c4]]
A17: 3.2 | B17: Phần tiền gửi dư thừa đủ điều kiện | C17: 0 | D17: 0 | E17: 0 | F17: 0 | G17: =SUM(C17:F17) | H17: =ThamSo!$E$63 | I17: =G17*H17 | J17: Khoản 8b Mục IV Phần C | K17: PL1.C.IV.8.b (raw dòng 1951); chưa có claim trong source note
A18: 4 | B18: Tiền gửi phát sinh từ hoạt động ngân hàng đại lý | C18: =C19+C20 | D18: =D19+D20 | E18: =E19+E20 | F18: =F19+F20 | G18: =G19+G20 | I18: =I19+I20
A19: 4.1 | B19: Tiền gửi từ hoạt động ngân hàng đại lý | C19: 0 | D19: 0 | E19: 0 | F19: 0 | G19: =SUM(C19:F19) | H19: =ThamSo!$E$64 | I19: =G19*H19 | J19: Khoản 9 Mục IV Phần C | K19: PL1.C.IV.9 (raw dòng 1953); chưa có claim trong source note
A20: 4.2 | B20: Phần tiền gửi dư thừa đủ điều kiện | C20: 0 | D20: 0 | E20: 0 | F20: 0 | G20: =SUM(C20:F20) | H20: =ThamSo!$E$65 | I20: =G20*H20 | J20: Khoản 9 Mục IV Phần C | K20: PL1.C.IV.9 (raw dòng 1953); chưa có claim trong source note
A21: 5 | B21: Các dòng tiền vào theo đối tác | C21: =C22+C23+C27 | D21: =D22+D23+D27 | E21: =E22+E23+E27 | F21: =F22+F23+F27 | G21: =G22+G23+G27 | I21: =I22+I23+I27 | J21: Mục IV Phần C
A22: 5.1 | B22: Khoản tiền phải thu từ khách hàng bán lẻ và doanh nghiệp nhỏ và vừa đủ điều kiện | C22: 300 | D22: 700 | E22: 800 | F22: 1800 | G22: =SUM(C22:F22) | H22: =ThamSo!$E$66 | I22: =G22*H22 | J22: Khoản 5 Mục IV Phần C | K22: PL1.C.IV.5 (raw dòng 1925); [[src-tt50-2026-nhnn#^pl1-c4]]
A23: 5.2 | B23: Khoản tiền phải thu từ doanh nghiệp, Chính phủ, tổ chức tài chính quốc tế, tổ chức công lập của Chính phủ | C23: =C24+C25+C26 | D23: =D24+D25+D26 | E23: =E24+E25+E26 | F23: =F24+F25+F26 | G23: =G24+G25+G26 | I23: =I24+I25+I26
A24: 5.2.1 | B24: Doanh nghiệp không phải tổ chức tài chính | C24: 400 | D24: 900 | E24: 1100 | F24: 2400 | G24: =SUM(C24:F24) | H24: =ThamSo!$E$67 | I24: =G24*H24 | J24: Điểm b(i) Khoản 6 Mục IV Phần C | K24: PL1.C.IV.6.b(i) (raw dòng 1933); [[src-tt50-2026-nhnn#^pl1-c4]]
A25: 5.2.2 | B25: Chính phủ; Kho bạc Nhà nước, Ủy ban nhân dân tỉnh, thành phố trực thuộc Trung ương; Bảo hiểm tiền gửi Việt Nam | C25: 0 | D25: 0 | E25: 0 | F25: 0 | G25: =SUM(C25:F25) | H25: =ThamSo!$E$68 | I25: =G25*H25 | J25: Điểm b(ii) khoản 6 Mục IV Phần C | K25: PL1.C.IV.6.b(ii) (raw dòng 1935); [[src-tt50-2026-nhnn#^pl1-c4]]
A26: 5.2.3 | B26: Các tổ chức khác | C26: 0 | D26: 0 | E26: 0 | F26: 0 | G26: =SUM(C26:F26) | H26: =ThamSo!$E$69 | I26: =G26*H26 | J26: Điểm b(iii), b(iv), b(v) khoản 6 Mục IV Phần C | K26: PL1.C.IV.6.b(iii)–(v) (raw dòng 1937); [[src-tt50-2026-nhnn#^pl1-c4]]
A27: 5.3 | B27: Khoản tiền phải thu từ tổ chức tài chính và Ngân hàng Nhà nước | C27: 800 | D27: 600 | E27: 500 | F27: 700 | G27: =SUM(C27:F27) | H27: =ThamSo!$E$70 | I27: =G27*H27 | J27: Khoản 6a Mục IV Phần C | K27: PL1.C.IV.6.a (raw dòng 1929); [[src-tt50-2026-nhnn#^pl1-c4]]
A28: 6 | B28: Dòng tiền vào ròng từ công cụ phái sinh | C28: 40 | D28: 90 | E28: 60 | F28: 150 | G28: =SUM(C28:F28) | H28: =ThamSo!$E$71 | I28: =G28*H28 | J28: Mục V Phần C | K28: PL1.C.V.1 (raw dòng 1957); chưa có claim trong source note
A29: 7 | B29: Dòng tiền vào từ chứng khoán đáo hạn trong vòng 30 ngày nhưng chứng khoán không thuộc danh mục HQLA đủ tiêu chuẩn | C29: 0 | D29: 300 | E29: 0 | F29: 500 | G29: =SUM(C29:F29) | H29: =ThamSo!$E$72 | I29: =G29*H29 | J29: Khoản 7 Mục IV Phần C | K29: PL1.C.IV.7 (raw dòng 1943); [[src-tt50-2026-nhnn#^pl1-c4]]
A30: Tổng dòng tiền vào | C30: =C6+C14+C15+C18+C21+C28+C29 | D30: =D6+D14+D15+D18+D21+D28+D29 | E30: =E6+E14+E15+E18+E21+E28+E29 | F30: =F6+F14+F15+F18+F21+F28+F29 | G30: =G6+G14+G15+G18+G21+G28+G29 | I30: =I6+I14+I15+I18+I21+I28+I29
